Workbook

Sheet Model Inputs
A1: UK Graduate Talent Pipeline — Model Inputs
A2: Update BLUE cells when new data is published. All other sheets recalculate automatically.
A4: GOVERNMENT FEE STRUCTURE
A5: Parameter | B5: Value | C5: Unit | D5: Source / Update Frequency
A6: Student visa application fee | B6: 490 | C6: GBP | D6: GOV.UK — updated annually
A7: PSW (Graduate) visa application fee | B7: 822 | C7: GBP | D7: GOV.UK — updated annually
A8: NHS surcharge rate (student, per year) | B8: 776 | C8: GBP/yr | D8: GOV.UK — updated annually
A9: NHS surcharge rate (PSW, per year) | B9: 1035 | C9: GBP/yr | D9: GOV.UK — updated annually
A10: Skilled Worker visa minimum salary | B10: 41700 | C10: GBP/yr | D10: GOV.UK — last changed Jul 2025
A11: Skilled Worker new entrant threshold | B11: 33400 | C11: GBP/yr | D11: GOV.UK — last changed Jul 2025
A12: Skilled Worker minimum hourly rate | B12: 17.13 | C12: GBP/hr | D12: GOV.UK — based on 48hr week
A14: UNIVERSITY FEE STRUCTURE
A15: Parameter | B15: Value | C15: Unit | D15: Source
A16: Average international MSc fee (non-London) | B16: 15500 | C16: GBP/yr | D16: HESA — updated annually
A17: Average international MSc fee (London) | B17: 22000 | C17: GBP/yr | D17: HESA — updated annually
A18: Domestic undergraduate fee cap | B18: 9535 | C18: GBP/yr | D18: DfE — last changed 2025
A19: International fee premium (multiplier) | B19: =B16/B18 | C19: x | D19: =B16/B18
A20: Total international fee income (sector) | B20: 10000000000 | C20: GBP | D20: HESA 2023/24
A21: International share of total fee income | B21: 0.45 | C21: % | D21: HESA — 45p of every pound
A23: LABOUR MARKET DATA
A24: Parameter | B24: Value | C24: Unit | D24: Source
A25: Median graduate salary (all subjects) | B25: 42000 | C25: GBP/yr | D25: ONS ASHE 2024
A26: Median postgraduate salary | B26: 47000 | C26: GBP/yr | D26: ONS ASHE 2024
A27: Entry-level data analyst salary | B27: 28000 | C27: GBP/yr | D27: Glassdoor/Indeed avg
A28: Entry-level data engineer salary | B28: 32000 | C28: GBP/yr | D28: Glassdoor/Indeed avg
A29: National Living Wage (hourly) | B29: 12.21 | C29: GBP/hr | D29: GOV.UK — April 2025
A30: PSW graduates earning within 1 month | B30: 0.62 | C30: % | D30: GOV.UK evaluation 2024
A31: PSW graduates in skilled employment | B31: 0.45 | C31: % | D31: Graduate Outcomes Survey
A32: PSW graduates in study-related work | B32: 0.65 | C32: % | D32: GOV.UK evaluation 2024

Sheet Pipeline Analysis
A1: UK Graduate Talent Pipeline — Calculated Analysis
A2: All values auto-calculate from Model Inputs sheet. Green cells = formulas.
A4: COST-BENEFIT: INTERNATIONAL MSc GRADUATE
A5: Metric | B5: Amount (GBP) | C5: Calculation | D5: Finding
A6: Total visa + NHS costs (student year) | B6: ='Model Inputs'!B6+'Model Inputs'!B8 | C6: Visa + 1yr NHS
A7: Total visa + NHS costs (PSW 2 years) | B7: ='Model Inputs'!B7+'Model Inputs'!B9*2 | C7: Visa + 2yr NHS
A8: Total government fees paid | B8: =B6+B7 | C8: Sum of above
A9: Tuition fee paid (non-London MSc) | B9: ='Model Inputs'!B16 | C9: Direct to university
A10: Total cost to study + stay 3 years | B10: =B8+B9 | C10: Fees + tuition
A11: Estimated living costs (3 years) | B11: 30000 | D11: 10k/yr average
A12: TOTAL INVESTMENT BY GRADUATE | B12: =B10+B11
A14: Revenue to UK per international MSc grad | B14: =B12 | D14: What the UK receives
A15: Skilled Worker salary threshold | B15: ='Model Inputs'!B10 | D15: What they need to earn to stay
A16: Typical entry salary achieved | B16: ='Model Inputs'!B27 | D16: What they actually earn
A17: SALARY GAP (threshold - reality) | B17: =B15-B16 | D17: This gap forces graduates out
A18: Gap as % of entry salary | B18: =B17/B16
A21: TALENT RETENTION RATE
A22: Metric | B22: Value | C22: Calculation | D22: Implication
A23: International students graduating per year (est) | B23: 200000 | D23: HESA estimate
A24: PSW visa uptake rate | B24: 0.6 | D24: Not all apply
A25: Graduates entering skilled employment | B25: ='Model Inputs'!B31
A26: Graduates who could meet salary threshold | B26: 0.15 | D26: Estimated 15% earn 41,700+
A27: Skilled Worker visa conversions (est) | B27: =B23*B26
A28: TALENT RETAINED (%) | B28: =B27/B23 | D28: Of all graduates
A29: TALENT LOST (%) | B29: =1-B28 | D29: Trained then exported
A30: Cost to train talent that leaves | B30: =B29*B12 | D30: Economic waste

Sheet Attainment Evidence
A1: A-Level Attainment by Ethnicity — Government Data
A2: Source: Department for Education, explore-education-statistics.service.gov.uk
A4: Ethnic Group | B4: Total Students | C4: Level 3 Achieved | D4: Rate (%) | E4: Gap from Best (pp)
A5: Asian or Asian British - Chinese | B5: 3221 | C5: 2876 | D5: 89.3 | E5: 0
A6: Asian or Asian British - Indian | B6: 18632 | C6: 15975 | D6: 85.7 | E6: -3.6
A7: Asian or Asian British - Bangladeshi | B7: 10374 | C7: 8202 | D7: 79.1 | E7: -10.2
A8: Asian or Asian British | B8: 69063 | C8: 54214 | D8: 78.5 | E8: -10.8
A9: Black or Black British - Black African | B9: 24720 | C9: 18874 | D9: 76.4 | E9: -12.9
A10: Any other ethnic group | B10: 11680 | C10: 8245 | D10: 70.6 | E10: -18.7
A11: Black or Black British | B11: 35544 | C11: 25099 | D11: 70.6 | E11: -18.7
A12: Asian or Asian British - Pakistani | B12: 25406 | C12: 17855 | D12: 70.3 | E12: -19
A13: Mixed Dual background | B13: 32388 | C13: 20430 | D13: 63.1 | E13: -26.2
A14: White | B14: 381396 | C14: 212822 | D14: 55.8 | E14: -33.5
A15: Black or Black British - Black Caribbean | B15: 6450 | C15: 3295 | D15: 51.1 | E15: -38.2
A18: ANALYST NOTE:
A19: Communities with strong immigration ties (Indian, Chinese, Black African) consistently
A20: achieve attainment rates at or above the national average. This contradicts the narrative
A21: that immigration lowers educational standards. The data shows the opposite.

Sheet Scenario Model
A1: What If? — Policy Scenario Modelling
A2: Change BLUE input cells to model different policy scenarios.
A4: SCENARIO: LOWER SALARY THRESHOLD
A5: Parameter | B5: Current | C5: Proposed | D5: Impact
A6: Salary threshold | B6: ='Model Inputs'!B10 | C6: 30000
A7: Entry-level data analyst salary | B7: ='Model Inputs'!B27 | C7: ='Model Inputs'!B27
A8: Gap (threshold - salary) | B8: =B6-B7 | C8: =C6-C7
A9: Can a data analyst qualify? | B9: =IF(B8>0,"NO","YES") | C9: =IF(C8>0,"NO","YES")
A10: Estimated additional graduates retained | C10: 25000 | D10: Per year estimate
A11: Additional tax revenue (20% rate) | C11: =C10*C6*0.2 | D11: Income tax alone
A12: Additional NI revenue | C12: =C10*C6*0.12 | D12: Employee NI
A13: Additional consumer spending | C13: =C10*C6*0.5 | D13: 50% spent in UK economy
A14: TOTAL ECONOMIC GAIN | C14: =C11+C12+C13
A17: SCENARIO: GRADUATE RETENTION PROGRAMME
A18: If the UK retained 50% of international MSc graduates for 5 years:
A19: Graduates retained per year | B19: 100000
A20: Average salary earned | B20: 35000
A21: Annual income tax generated | B21: =B19*B20*0.2
A22: Annual NI generated | B22: =B19*B20*0.12
A23: TOTAL TAX REVENUE OVER 5 YEARS | B23: =(B21+B22)*5

Sheet Findings
A1: UK Graduate Talent Pipeline — Findings & Recommendations
A3: # | B3: Finding
A4: 1 | B4: The UK higher education sector generates 10B/year from international students — 20% of total income. This is an export industry, not a charity.
A5: 2 | B5: The Skilled Worker visa salary threshold (41,700) exceeds the entry-level salary for most graduate professions (25-32k). This creates a structural barrier that prevents graduates from transitioning to sponsored employment.
A6: 3 | B6: Only 45% of PSW graduates secure skilled employment. 35% work in hospitality, retail, or warehouse roles despite holding postgraduate qualifications.
A7: 4 | B7: Government data shows that students from immigrant-background communities (Indian, Chinese, Black African) consistently achieve attainment rates at or above the national average at A-Level. Immigration strengthens educational outcomes.
A8: 5 | B8: Deprivation is a stronger predictor of attainment than ethnicity. The attainment gap between disadvantaged and non-disadvantaged students within the same ethnic group exceeds the gap between ethnic groups.
A9: 6 | B9: The attainment gap has not significantly narrowed over 10 years of widening participation policy. Current interventions are insufficient.
A10: 7 | B10: The current pipeline model extracts maximum revenue from international students (tuition + visa fees + NHS surcharge) then structurally prevents most from contributing to the UK labour market. This represents an economic inefficiency.
A13: # | B13: Recommendation
A14: R1 | B14: Introduce a post-study salary threshold aligned with actual graduate salaries (28-30k) rather than the general Skilled Worker threshold (41,700). This retains skilled graduates who are ready to contribute.
A15: R2 | B15: Create a Graduate Retention Pathway allowing graduates in shortage occupations to transition to Skilled Worker visas at a reduced salary threshold for the first 3 years.
A16: R3 | B16: Publish annual data on PSW graduate employment outcomes by subject, university, and salary band. Current reporting lacks the granularity needed for evidence-based policy.
... A18: R5 | B18: Address deprivation as the primary driver of the attainment gap, rather than ethnicity. Current policy focuses on the wrong variable.
A21: DATA
B22: Department for Education — explore-education-statistics.service.gov.uk
B23: HESA Higher Education Student Statistics — hesa.ac.uk
B24: GOV.UK Graduate Route Evaluation — gov.uk/government/publications/graduate-route-evaluation
B25: ONS Annual Survey of Hours and Earnings — ons.gov.uk
A27: AUTHOR
B28: Pawan Singh Kapkoti — MSc Data Analytics, Aston University
B29: Microsoft Certified: Power BI Data Analyst Associate (PL-300)
B30: github.com/Pawansingh3889 | linkedin.com/in/pawan-singh-kapkoti-100176347

Sheet Case Study - Graduate Profile
A1: Case Study: Single Graduate Pipeline Journey
A2: One data point in the pipeline. Update blue cells to model any graduate.
A4: GRADUATE PROFILE (Updateable)
A5: Field | B5: Value | C5: Unit | D5: Notes
A6: Name | B6: Pawan Singh Kapkoti
A7: Nationality | B7: Indian
A8: Qualification | B8: MSc Data Analytics | D8: Aston University, 2:1
A9: Graduation date | B9: March 2024
A10: Visa type | B10: PSW (Graduate Route) | D10: 2 year duration
A11: Visa expiry | B11: May 2026
A12: Days remaining (as of analysis) | B12: 42 | C12: days | D12: Auto-update when reviewing
A13: Certifications earned in UK | B13: PL-300, Google Data Analytics | D13: Self-funded, self-studied
A14: Portfolio projects built | B14: 10 | D14: All public on GitHub
A15: Target role | B15: Data Analyst / Data Engineer | D15: SOC 3544 / 3133
A16: Target salary | B16: 28000 | C16: GBP/yr | D16: Entry level data analyst
A19: INVESTMENT INTO UK ECONOMY
A20: Item | B20: Amount (GBP) | C20: Recipient | D20: Type
A21: MSc tuition fee | B21: 15000 | C21: Aston University | D21: Education
A22: Student visa fee | B22: 490 | C22: Home Office | D22: Government fee
A23: NHS surcharge (student, 1 year) | B23: 776 | C23: NHS / Treasury | D23: Healthcare access
A24: PSW visa fee | B24: 822 | C24: Home Office | D24: Government fee
A25: NHS surcharge (PSW, 2 years) | B25: 2070 | C25: NHS / Treasury | D25: Healthcare access
A26: Living costs (rent, food, bills - 30 months) | B26: 25000 | C26: UK landlords, businesses | D26: Consumer spending
A27: PL-300 exam fee | B27: 165 | C27: Microsoft (UK operation) | D27: Certification
A28: Income tax paid (20 months employment) | B28: 3200 | C28: HMRC | D28: Tax revenue
A29: National Insurance paid (20 months) | B29: 2400 | C29: HMRC | D29: Tax revenue
A30: Council tax paid (20 months) | B30: 1600 | C30: Hull City Council | D30: Local government
A31: TOTAL INVESTED INTO UK | B31: =SUM(B21:B30)
A33: WHAT THE UK GOT BACK
A34: Metric | B34: Value | C34: Unit | D34: Source
A35: Tax + NI contributed | B35: 5600 | C35: GBP | D35: Payslip data
A36: Consumer spending in UK economy | B36: 25000 | C36: GBP | D36: Rent, food, transport, retail
A37: NHS services consumed | B37: 150 | C37: GBP | D37: One A&E visit (estimated NHS cost)
A38: Prescription cost paid by graduate | B38: 15 | C38: GBP | D38: Out of pocket
A39: NHS payments made (NI share + IHS) | B39: 4609 | C39: GBP | D39: NI allocation + Immigration Health Surcharge
A40: NHS payment-to-usage ratio | B40: =B39/B37 | C40: x
A41: Net NHS surplus from this graduate | B41: =B39-B37 | C41: GBP
A42: Total tax + fees paid to government | B42: =B35+B39+B21+B22+B23+B24 | C42: GBP
A43: Tuition paid to university | B43: 15000 | C43: GBP
A44: TOTAL UK REVENUE FROM THIS GRADUATE | B44: =B42+B43 | C44: GBP
...
